package academy.devdojo.mainjava.javacore.Oexception.runtime.test;
//O bloco finally sempre vai ser chamado
public class RuntimeExceptionTest03 {
    public static void main(String[] args) {
        abreConexao2();
    }

    private static String abreConexao() {
        try {
            System.out.println("Abrindo arquivo");
            System.out.println("Escrevendo dados no arquivo");
            return "Conex√£o aberta";
        } catch (Exception e) {
            e.printStackTrace();
        } finally {
            System.out.println("Fechando recurso liberado pelo SO");
        }
        return null;
    }

    private static void abreConexao2() {
        try {
            System.out.println("Abrindo arquivo");
            System.out.println("Escrevendo dados no arquivo");
            throw new RuntimeException();
        } finally {
            System.out.println("Fechando recurso liberado pelo SO"); //sempre vai ser chamado
        }
    }
}
